Workbook

Sheet Meta information
A1: Project: Ecosystem modeling of mesocosm studies
A2: Documentation of model inputs for model:
A4: Tables included:
A5: Input parameters | B5: List of model input parameters and detailed documentation of parameter estimation (see description of columns below)
A6: Intermediary parameters | B6: List of parameters used to calculate or estimate model input parameters (e.g., conversion factors, etc.; see description of columns below)
A7: Input files | B7: List of input files used by the model (e.g., daily weather data); if model parameters are defined in input files, the individual parameters also need to be documented in the input parameter table as well
A8: Unused references | B8: According to the EFSA good modeling practice (2014), all data available to parameterize a model should be used. If a relevant data source is not used, a justification is needed. This table lists the unused reference along with a justification.
A10: Columns in 'Input parameters'
A11: Parameter name | B11: Name of the parameter used in the model description
A12: Name in code | B12: Name of parameter in the model code
A13: Input method | B13: Description of how parameter is fed into the model, e.g., interface, input file (include file name)
A14: Unit | B14: Parameter unit
A15: Biological name/meaning | B15: Corresponding name or meaning of the parameter in the real system(e.g., wet weight)
A16: Estimated value | B16: Parameter value used as baseline
A17: Uncertainty (min, max of 95% interval or range of reported values) | B17: Biologically relevant range of parameter values
A18: References (including page #, table #, etc.) | B18: References used for parameter estimation including details such as page, table and/or figure number, version number or access date for online data bases; if other relevant references reporting data for the estimation of the parameter are avaialbe, but were not used, note "see unused references" and list those on sheet "Unused references" along with a justification why the references were not used.
A19: Species used in measurement | B19: Species for which the data used for parameter estimation was reported in the references
A20: Experimental setting of measurement | B20: Summary of experimental setting and design reported in the references, including laboratory conditions or location and time of field setting, sample sizes etc. Detailed description of the studies or data sets used for parameterization, including an assessment of data quality, to be included in the TRACE documentation (provide corresponding section and page number).
A21: Justification of relevance | B21: Justification for the use of the data source if species or experimental setting differ from mesocosm study: why is the data source relevant for model parameterization nevertheless? In addition to a brief summary here, you can provide a reference to the TRACE documentation (including section and page number).
A22: Estimation method (direct use of data, derived from literature source, model calibration) | B22: General approach used for parameter estimation
... A24: External files used for parameter estimation (e.g., scripts, tables, etc.) | B24: External files used for the parameter estimation and short description of files or description of methodology; include reference to TRACE documentation (including section and page number) if applicable
A26: Columns in 'Input files'
A27: Type of data in input file (e.g., daily temperature) | B27: List each type of data read from file by the model separately even if multiple data types are included in a single input file
A28: File name in which data is contained | B28: Name of the input file in which the data is contained
A29: Unit(s) of data | B29: Units of the data set
A30: Format of data (e.g., number of data points included) | B30: Format of data needed in the input file, including, e.g., temporal resolution, number of data entries, etc.
A31: Name/meaning in real system | B31: Name or meaning of the data in the corresponding real system
A32: Description of uncertainty of data in the input file | B32: Uncertainty in the input data
A33: References (including page #, table #, etc.) | B33: References used for compilation of input data including details such as page, table and/or figure number, version number or access date for online data bases; if other relevant references reporting data for the estimation of the parameter are avaialbe, but were not used, note "see unused references" and list those on sheet "Unused references" along with a justification why the references were not used
A34: Description of system from which data originates | B34: Location, time of measurements taken; differences between system from which data were taken and the specific mesocosms used for the current study
A35: Estimation method (direct use of data, derived from original source, etc.) | B35: Method used for data estimation
A36: Justification of relevance | B36: Justification for the use of the data source if species or experimental setting differ from mesocosm study: why is the data source relevant for model parameterization nevertheless? In addition to a brief summary here, you can provide a reference to the TRACE documentation (including section and page number).
A37: Description of methods and intermediary parameters used for compilation of input data (or reference to separate document) | B37: Description of methods used to derive or estimate the input values and uncertainty from empirical data, intermediary parameters (see separate sheet) applied; provide detailed method description as applicable in the TRACE documentation, and include reference to section and page number
A38: External files used for data estimation/ compilation (e.g., scripts, tables, etc.) or description of methodology | B38: External files used for the parameter estimation and short description of files or description of methodology; include reference to TRACE documentation (including section and page number) if applicable
A40: Columns in 'Intermediary parameters'
A41: Name of intermediary parameter | B41: Name of the intermediary parameter used in the model description
A42: Used in the calculation/ estimation of model parameter(s) | B42: Name of the model input parameter(s) or input data that use the intermediary parameter for their estimation or calculation
A43: Unit | B43: Parameter unit
A44: Biological name/meaning | B44: Corresponding name or meaning of the parameter in the real system (e.g., wet weight)
A45: Estimated value | B45: Parameter value used as baseline
...

Sheet Input parameters
A1: Parameter name | B1: Name in code | C1: Input method | D1: Unit | E1: Biological name/meaning | F1: Distribution | G1: Prior mean | H1: Prior SD | I1: Prior minimum value | J1: Prior maximum value | K1: Calibrated mean | L1: Calibrated sd | M1: References (including page #, table #, etc.) | N1: Species used in measurement | O1: Experimental setting of measurement | P1: Justification of relevance | Q1: Estimation method (direct use of data, derived from literature source, calibration) | R1: Calibrated? | S1: Description of methods and intermediary parameters used for parameter estimation (or reference to separate document) | T1: External files used for parameter estimation (e.g., scripts, tables, etc.) or description of methodology | U1: Source type
A2: Global parameters
A3: kBoltzmann | B3: n.a. | C3: implemented (no input required) | D3: eV/K | E3: Boltzman constant | F3: n.a. | G3: 8.61734e-05 | I3: - | J3: - | K3: - | L3: - | M3: - | N3: - | O3: - | P3: - | Q3: derived from literature | R3: no | U3: L
A4: Universal parameters for phytoplankton and periphyton
A5: αC,Algae | B5: Algae_aC | C5: parameter_input.dat | D5: gC/gAlgae | E5: Carbon content of Algae | F5: none | G5: 0.36 | I5: - | J5: - | K5: - | L5: - | M5: Redfield, CA 1958: The biological control of chemical factors in the environment. American scientist. September 1958. | P5: overarching principles | Q5: derived from literature | R5: no | U5: L
A6: αO,Algae | B6: Algae_aO | C6: parameter_input.dat | D6: gO/gAlgae | E6: Oxygen content of Algae | F6: none | G6: 0.5 | I6: - | J6: - | K6: - | L6: - | M6: Redfield, CA 1958: The biological control of chemical factors in the environment. American scientist. September 1958. | P6: overarching principles | Q6: derived from literature | R6: no | U6: L
A7: αH,Algae | B7: Algae_aH | C7: parameter_input.dat | D7: gH/gAlgae | E7: Hydrogen content of Algae | F7: none | G7: 0.07 | I7: - | J7: - | K7: - | L7: - | M7: Redfield, CA 1958: The biological control of chemical factors in the environment. American scientist. September 1958. | P7: overarching principles | Q7: derived from literature | R7: no | U7: L
A8: αN,Algae | B8: Algae_aN | C8: parameter_input.dat | D8: gN/gAlgae | E8: Nitrogen content of Algae | F8: none | G8: 0.06 | I8: - | J8: - | K8: - | L8: - | M8: Redfield, CA 1958: The biological control of chemical factors in the environment. American scientist. September 1958. | P8: overarching principles | Q8: derived from literature | R8: no | U8: L
A9: αP,Algae | B9: Algae_aP | C9: parameter_input.dat | D9: gP/gAlgae | E9: Phosphorous content of Algae | F9: none | G9: 0.01 | I9: - | J9: - | K9: - | L9: - | M9: Redfield, CA 1958: The biological control of chemical factors in the environment. American scientist. September 1958. | P9: overarching principles | Q9: derived from literature | R9: no | U9: L
A10: EC | B10: Algae_EC | C10: parameter_input.dat | D10: J/gAFDM | E10: Energy content | F10: lognormal | G10: 20000 | H10: 2000 | I10: - | J10: - | K10: =VLOOKUP(B10,Tabelle1!$A$1:$C$351,2,FALSE) -> 20146.32 | L10: =VLOOKUP(B10,Tabelle1!$A$1:$C$351,3,FALSE) -> 1997.2269 | M10: Cummins KW (1971). Calorific equivalents for studies in ecological energetics. Internationale Vereinigung für theoretische und angewandte Limnologie. Mitteilung No. 18. Table. on p.10 "Algae". // Jørgensen, S.E., Nielsen, S.N., Jørgensen, L.A., 1991. Handbook of Ecological Parameters and Ecotoxicology. Elsevier, Amsterdam. // Runck C (2007). Macroinvertebrate production and food web energetics in an industrially contaminated stream. Ecological Applications, 17, 740-753. Fig 4 | N10: Cummins: various algae. // Runck: Periphyton | O10: Runck: in contaminated, nutrient-enriched stream stream | P10: overarching principles | Q10: value derived from literature source as prior and then calibrated | R10: yes | S10: Cummins: Suggested value for algea based on literature review (mean of 396 samples). // Runck: Periphyton in contaminated, nutrient-enriched stream stream | T10: - | U10: L
A11: i0 | B11: Algae_i0 | C11: parameter_input.dat | D11: J/yr | E11: Normalization constant for metabolic rates | F11: lognormal | G11: =60*60*24*365.25*131.52 -> 4.1504556e+09 | H11: 1530000000 | I11: - | J11: - | K11: =VLOOKUP(B11,Tabelle1!$A$1:$C$351,2,FALSE) -> 3.7549316e+09 | L11: =VLOOKUP(B11,Tabelle1!$A$1:$C$351,3,FALSE) -> 1.41494e+09 | M11: Tang E.P.Y. & Peters R.H. (1995). The allometry of algal respiration. Journal of Plankton Research, 17, 303-315. | N11: study collected data from literature and built the regression model. Collected data: 178 data entries representing 37 different species and six divisions and then | O11: study standardized all data to 20°C | P11: same value for prior as has been used for periphyton. | Q11: value derived from literature source as prior and then calibrated | R11: yes | U11: L
A12: b | B12: Algae_b | C12: parameter_input.dat | D12: - | E12: Allometric scaling exponent | F12: lognormal | G12: 0.93 | H12: 0.033 | I12: - | J12: - | K12: =VLOOKUP(B12,Tabelle1!$A$1:$C$351,2,FALSE) -> 0.93918975 | L12: =VLOOKUP(B12,Tabelle1!$A$1:$C$351,3,FALSE) -> 0.03407624 | M12: Tang E.P.Y. & Peters R.H. (1995). The allometry of algal respiration. Journal of Plankton Research, 17, 303-315. p.307 | N12: study collected data from literature and built the regression model. Collected data: 178 data entries representing 37 different species and six divisions and then | O12: study standardized all data to 20°C | P12: same value for prior as has been used for periphyton. | Q12: direct use of data as prior and then calibrated | R12: yes | U12: L
A13: M0 | B13: n.a. | C13: implemented (no input required) | D13: gAFDM | E13: normalization constant | F13: none | G13: 1 | I13: - | J13: - | K13: - | L13: - | M13: n.a. | N13: - | O13: - | P13: - | Q13: - | R13: no | U13: M
A14: Taxon-specific parameters for phytoplankton
A15: Dini | B15: PhBlueGreens_Co14a_hab1_Dini | C15: parameter_input.dat | D15: gDM/m2 | E15: Initial algae density | F15: lognormal | G15: 0.0058 | H15: =G15*0.1 -> 0.00058 | I15: - | J15: - | K15: =VLOOKUP(B15,Tabelle1!$A$1:$C$351,2,FALSE) -> 0.0057926256 | L15: =VLOOKUP(B15,Tabelle1!$A$1:$C$351,3,FALSE) -> 0.00058310779 | M15: Mesocosm GmbH | N15: Blue Greens | O15: Measurements as described by Mesocosm GmbH | P15: This was the experimental data to be modelled | Q15: derived from experimental data and then calibrated | R15: yes | S15: Calculated from first measurment and converted to gDM/m2 using the conversion factors listed in "intermediary parameters" and the individual biomass M | T15: Chunk 1.4, function convert.exp.to.biomass, | U15: S
A16: Dini | B16: PhBlueGreens_Co16a_hab1_Dini | C16: parameter_input.dat | D16: gDM/m2 | E16: Initial algae density | F16: lognormal | G16: 0.0925 | H16: =G16*0.1 -> 0.00925 | I16: - | J16: - | K16: =VLOOKUP(B16,Tabelle1!$A$1:$C$351,2,FALSE) -> 0.091953575 | L16: =VLOOKUP(B16,Tabelle1!$A$1:$C$351,3,FALSE) -> 0.0087426929 | M16: Mesocosm GmbH | N16: Blue Greens | O16: Measurements as described by Mesocosm GmbH | P16: This was the experimental data to be modelled | Q16: derived from experimental data and then calibrated | R16: yes | S16: Calculated from first measurment and converted to gDM/m2 using the conversion factors listed in "intermediary parameters" and the individual biomass M | T16: Chunk 1.4, function convert.exp.to.biomass, | U16: S
A17: Dini | B17: PhBlueGreens_Co18c_hab1_Dini | C17: parameter_input.dat | D17: gDM/m2 | E17: Initial algae density | F17: lognormal | G17: 0.0626 | H17: =G17*0.1 -> 0.00626 | I17: - | J17: - | K17: =VLOOKUP(B17,Tabelle1!$A$1:$C$351,2,FALSE) -> 0.062485875 | L17: =VLOOKUP(B17,Tabelle1!$A$1:$C$351,3,FALSE) -> 0.0063566266 | M17: Mesocosm GmbH | N17: Blue Greens | O17: Measurements as described by Mesocosm GmbH | P17: This was the experimental data to be modelled | Q17: derived from experimental data and then calibrated | R17: yes | S17: Calculated from first measurment and converted to gDM/m2 using the conversion factors listed in "intermediary parameters" and the individual biomass M | T17: Chunk 1.4, function convert.exp.to.biomass, | U17: S
A18: Dini | B18: PhBlueGreens_Co19b_hab1_Dini | C18: parameter_input.dat | D18: gDM/m2 | E18: Initial algae density | F18: lognormal | G18: 0.0209 | H18: =G18*0.1 -> 0.00209 | I18: - | J18: - | K18: =VLOOKUP(B18,Tabelle1!$A$1:$C$351,2,FALSE) -> 0.020980194 | L18: =VLOOKUP(B18,Tabelle1!$A$1:$C$351,3,FALSE) -> 0.0020834483 | M18: Mesocosm GmbH | N18: Blue Greens | O18: Measurements as described by Mesocosm GmbH | P18: This was the experimental data to be modelled | Q18: derived from experimental data and then calibrated | R18: yes | S18: Calculated from first measurment and converted to gDM/m2 using the conversion factors listed in "intermediary parameters" and the individual biomass M | T18: Chunk 1.4, function convert.exp.to.biomass, | U18: S
A19: Dini | B19: PhCryptophytes_Co14a_hab1_Dini | C19: parameter_input.dat | D19: gDM/m2 | E19: Initial algae density | F19: lognormal | G19: 0.0713 | H19: =G19*0.1 -> 0.00713 | I19: - | J19: - | K19: =VLOOKUP(B19,Tabelle1!$A$1:$C$351,2,FALSE) -> 0.071066919 | L19: =VLOOKUP(B19,Tabelle1!$A$1:$C$351,3,FALSE) -> 0.0068777105 | M19: Mesocosm GmbH | N19: Cryptophytes | O19: Measurements as described by Mesocosm GmbH | P19: This was the experimental data to be modelled | Q19: derived from experimental data and then calibrated | R19: yes | S19: Calculated from first measurment and converted to gDM/m2 using the conversion factors listed in "intermediary parameters" and the individual biomass M | T19: Chunk 1.4, function convert.exp.to.biomass, | U19: S
A20: Dini | B20: PhCryptophytes_Co16a_hab1_Dini | C20: parameter_input.dat | D20: gDM/m2 | E20: Initial algae density | F20: lognormal | G20: 0.239734 | H20: =G20*0.1 -> 0.0239734 | I20: - | J20: - | K20: =VLOOKUP(B20,Tabelle1!$A$1:$C$351,2,FALSE) -> 0.24078281 | L20: =VLOOKUP(B20,Tabelle1!$A$1:$C$351,3,FALSE) -> 0.023960561 | M20: Mesocosm GmbH | N20: Cryptophytes | O20: Measurements as described by Mesocosm GmbH | P20: This was the experimental data to be modelled | Q20: derived from experimental data and then calibrated | R20: yes | S20: Calculated from first measurment and converted to gDM/m2 using the conversion factors listed in "intermediary parameters" and the individual biomass M | T20: Chunk 1.4, function convert.exp.to.biomass, | U20: S
A21: Dini | B21: PhCryptophytes_Co18c_hab1_Dini | C21: parameter_input.dat | D21: gDM/m2 | E21: Initial algae density | F21: lognormal | G21: 0.14 | H21: =G21*0.1 -> 0.014 | I21: - | J21: - | K21: =VLOOKUP(B21,Tabelle1!$A$1:$C$351,2,FALSE) -> 0.14027162 | L21: =VLOOKUP(B21,Tabelle1!$A$1:$C$351,3,FALSE) -> 0.014351562 | M21: Mesocosm GmbH | N21: Cryptophytes | O21: Measurements as described by Mesocosm GmbH | P21: This was the experimental data to be modelled | Q21: derived from experimental data and then calibrated | R21: yes | S21: Calculated from first measurment and converted to gDM/m2 using the conversion factors listed in "intermediary parameters" and the individual biomass M | T21: Chunk 1.4, function convert.exp.to.biomass, | U21: S
A22: Dini | B22: PhCryptophytes_Co19b_hab1_Dini | C22: parameter_input.dat | D22: gDM/m2 | E22: Initial algae density | F22: lognormal | G22: 0.0581 | H22: =G22*0.1 -> 0.00581 | I22: - | J22: - | K22: =VLOOKUP(B22,Tabelle1!$A$1:$C$351,2,FALSE) -> 0.058895688 | L22: =VLOOKUP(B22,Tabelle1!$A$1:$C$351,3,FALSE) -> 0.0056638771 | M22: Mesocosm GmbH | N22: Cryptophytes | O22: Measurements as described by Mesocosm GmbH | P22: This was the experimental data to be modelled | Q22: derived from experimental data and then calibrated | R22: yes | S22: Calculated from first measurment and converted to gDM/m2 using the conversion factors listed in "intermediary parameters" and the individual biomass M | T22: Chunk 1.4, function convert.exp.to.biomass, | U22: S
A23: Dini | B23: PhDiatoms_Co14a_hab1_Dini | C23: parameter_input.dat | D23: gDM/m2 | E23: Initial algae density | F23: lognormal | G23: 0.106 | H23: =G23*0.1 -> 0.0106 | I23: - | J23: - | K23: =VLOOKUP(B23,Tabelle1!$A$1:$C$351,2,FALSE) -> 0.1073024 | L23: =VLOOKUP(B23,Tabelle1!$A$1:$C$351,3,FALSE) -> 0.0099758311 | M23: Mesocosm GmbH | N23: Diatoms | O23: Measurements as described by Mesocosm GmbH | P23: This was the experimental data to be modelled | Q23: derived from experimental data and then calibrated | R23: yes | S23: Calculated from first measurment and converted to gDM/m2 using the conversion factors listed in "intermediary parameters" and the individual biomass M | T23: Chunk 1.4, function convert.exp.to.biomass, | U23: S
A24: Dini | B24: PhDiatoms_Co16a_hab1_Dini | C24: parameter_input.dat | D24: gDM/m2 | E24: Initial algae density | F24: lognormal | G24: 0.202053 | H24: =G24*0.1 -> 0.0202053 | I24: - | J24: - | K24: =VLOOKUP(B24,Tabelle1!$A$1:$C$351,2,FALSE) -> 0.20127283 | L24: =VLOOKUP(B24,Tabelle1!$A$1:$C$351,3,FALSE) -> 0.019504215 | M24: Mesocosm GmbH | N24: Diatoms | O24: Measurements as described by Mesocosm GmbH | P24: This was the experimental data to be modelled | Q24: derived from experimental data and then calibrated | R24: yes | S24: Calculated from first measurment and converted to gDM/m2 using the conversion factors listed in "intermediary parameters" and the individual biomass M | T24: Chunk 1.4, function convert.exp.to.biomass, | U24: S
A25: Dini | B25: PhDiatoms_Co18c_hab1_Dini | C25: parameter_input.dat | D25: gDM/m2 | E25: Initial algae density | F25: lognormal | G25: 0.0846 | H25: =G25*0.1 -> 0.00846 | I25: - | J25: - | K25: =VLOOKUP(B25,Tabelle1!$A$1:$C$351,2,FALSE) -> 0.085282648 | L25: =VLOOKUP(B25,Tabelle1!$A$1:$C$351,3,FALSE) -> 0.0087548232 | M25: Mesocosm GmbH | N25: Diatoms | O25: Measurements as described by Mesocosm GmbH | P25: This was the experimental data to be modelled | Q25: derived from experimental data and then calibrated | R25: yes | S25: Calculated from first measurment and converted to gDM/m2 using the conversion factors listed in "intermediary parameters" and the individual biomass M | T25: Chunk 1.4, function convert.exp.to.biomass, | U25: S
A26: Dini | B26: PhDiatoms_Co19b_hab1_Dini | C26: parameter_input.dat | D26: gDM/m2 | E26: Initial algae density | F26: lognormal | G26: 0.0514 | H26: =G26*0.1 -> 0.00514 | I26: - | J26: - | K26: =VLOOKUP(B26,Tabelle1!$A$1:$C$351,2,FALSE) -> 0.051420652 | L26: =VLOOKUP(B26,Tabelle1!$A$1:$C$351,3,FALSE) -> 0.0051992569 | M26: Mesocosm GmbH | N26: Diatoms | O26: Measurements as described by Mesocosm GmbH | P26: This was the experimental data to be modelled | Q26: derived from experimental data and then calibrated | R26: yes | S26: Calculated from first measurment and converted to gDM/m2 using the conversion factors listed in "intermediary parameters" and the individual biomass M | T26: Chunk 1.4, function convert.exp.to.biomass, | U26: S
... A30: Dini | B30: PhGreens_Co19b_hab1_Dini | C30: parameter_input.dat | D30: gDM/m2 | E30: Initial algae density | F30: lognormal | G30: 0.0274 | H30: =G30*0.1 -> 0.00274 | I30: - | J30: - | K30: =VLOOKUP(B30,Tabelle1!$A$1:$C$351,2,FALSE) -> 0.027614678 | L30: =VLOOKUP(B30,Tabelle1!$A$1:$C$351,3,FALSE) -> 0.002805429 | M30: Mesocosm GmbH | N30: Greens | O30: Measurements as described by Mesocosm GmbH | P30: This was the experimental data to be modelled | Q30: derived from experimental data and then calibrated | R30: yes | S30: Calculated from first measurment and converted to gDM/m2 using the conversion factors listed in "intermediary parameters" and the individual biomass M | T30: Chunk 1.4, function convert.exp.to.biomass, | U30: S
A31: Ea | B31: PhBlueGreens_Ea | C31: parameter_input.dat | D31: eV | E31: Activation energy | F31: lognormal | G31: 0.231 | H31: 0.1155 | I31: - | J31: - | K31: =VLOOKUP(B31,Tabelle1!$A$1:$C$351,2,FALSE) -> 0.24440163 | L31: =VLOOKUP(B31,Tabelle1!$A$1:$C$351,3,FALSE) -> 0.11230904 | M31: Tang E.P.Y. & Peters R.H. (1995). The allometry of algal respiration. Journal of Plankton Research, 17, 303-315. | N31: study collected data from literature and built the regression model. Collected data: 178 data entries representing 37 different species and six divisions and then | O31: study standardized all data to 20°C | P31: same value for prior as has been used for periphyton. | Q31: value derived from literature source as prior and then calibrated | R31: yes | U31: L
A32: Ea | B32: PhCryptophytes_Ea | C32: parameter_input.dat | D32: eV | E32: Activation energy | F32: lognormal | G32: 0.231 | H32: 0.1155 | I32: - | J32: - | K32: =VLOOKUP(B32,Tabelle1!$A$1:$C$351,2,FALSE) -> 0.23419695 | L32: =VLOOKUP(B32,Tabelle1!$A$1:$C$351,3,FALSE) -> 0.11438043 | M32: Tang E.P.Y. & Peters R.H. (1995). The allometry of algal respiration. Journal of Plankton Research, 17, 303-315. | N32: study collected data from literature and built the regression model. Collected data: 178 data entries representing 37 different species and six divisions and then | O32: study standardized all data to 20°C | P32: same value for prior as has been used for periphyton. | Q32: value derived from literature source as prior and then calibrated | R32: yes | U32: L
A33: Ea | B33: PhDiatoms_Ea | C33: parameter_input.dat | D33: eV | E33: Activation energy | F33: lognormal | G33: 0.231 | H33: 0.1155 | I33: - | J33: - | K33: =VLOOKUP(B33,Tabelle1!$A$1:$C$351,2,FALSE) -> 0.2377573 | L33: =VLOOKUP(B33,Tabelle1!$A$1:$C$351,3,FALSE) -> 0.10591389 | M33: Tang E.P.Y. & Peters R.H. (1995). The allometry of algal respiration. Journal of Plankton Research, 17, 303-315. | N33: study collected data from literature and built the regression model. Collected data: 178 data entries representing 37 different species and six divisions and then | O33: study standardized all data to 20°C | P33: same value for prior as has been used for periphyton. | Q33: value derived from literature source as prior and then calibrated | R33: yes | U33: L
A34: Ea | B34: PhGreens_Ea | C34: parameter_input.dat | D34: eV | E34: Activation energy | F34: lognormal | G34: 0.231 | H34: 0.1155 | I34: - | J34: - | K34: =VLOOKUP(B34,Tabelle1!$A$1:$C$351,2,FALSE) -> 0.23875579 | L34: =VLOOKUP(B34,Tabelle1!$A$1:$C$351,3,FALSE) -> 0.10831492 | M34: Tang E.P.Y. & Peters R.H. (1995). The allometry of algal respiration. Journal of Plankton Research, 17, 303-315. | N34: study collected data from literature and built the regression model. Collected data: 178 data entries representing 37 different species and six divisions and then | O34: study standardized all data to 20°C | P34: same value for prior as has been used for periphyton. | Q34: value derived from literature source as prior and then calibrated | R34: yes | U34: L
A35: fbasaltax | B35: PhBlueGreens_fbasaltax | C35: parameter_input.dat | D35: - | E35: Taxon-specific modification factor regarding basal metabolism | F35: Normal truncated | G35: 1 | H35: 0.25 | I35: 0.01 | J35: 1.99 | K35: =VLOOKUP(B35,Tabelle1!$A$1:$C$351,2,FALSE) -> 1.0063585 | L35: =VLOOKUP(B35,Tabelle1!$A$1:$C$351,3,FALSE) -> 0.24451549 | M35: starting value for prior based on mechanistic considerations | N35: - | O35: - | P35: - | Q35: - | R35: yes | S35: - | T35: - | U35: M
A36: fbasaltax | B36: PhCryptophytes_fbasaltax | C36: parameter_input.dat | D36: - | E36: Taxon-specific modification factor regarding basal metabolism | F36: Normal truncated | G36: 1 | H36: 0.25 | I36: 0.01 | J36: 1.99 | K36: =VLOOKUP(B36,Tabelle1!$A$1:$C$351,2,FALSE) -> 0.99797663 | L36: =VLOOKUP(B36,Tabelle1!$A$1:$C$351,3,FALSE) -> 0.24955705 | M36: starting value for prior based on mechanistic considerations | N36: - | O36: - | P36: - | Q36: - | R36: yes | S36: - | T36: - | U36: M
A37: fbasaltax | B37: PhDiatoms_fbasaltax | C37: parameter_input.dat | D37: - | E37: Taxon-specific modification factor regarding basal metabolism | F37: Normal truncated | G37: 1 | H37: 0.25 | I37: 0.01 | J37: 1.99 | K37: =VLOOKUP(B37,Tabelle1!$A$1:$C$351,2,FALSE) -> 0.9953185 | L37: =VLOOKUP(B37,Tabelle1!$A$1:$C$351,3,FALSE) -> 0.24860952 | M37: starting value for prior based on mechanistic considerations | N37: - | O37: - | P37: - | Q37: - | R37: yes | S37: - | T37: - | U37: M
A38: fbasaltax | B38: PhGreens_fbasaltax | C38: parameter_input.dat | D38: - | E38: Taxon-specific modification factor regarding basal metabolism | F38: Normal truncated | G38: 1 | H38: 0.25 | I38: 0.01 | J38: 1.99 | K38: =VLOOKUP(B38,Tabelle1!$A$1:$C$351,2,FALSE) -> 1.012954 | L38: =VLOOKUP(B38,Tabelle1!$A$1:$C$351,3,FALSE) -> 0.25106264 | M38: starting value for prior based on mechanistic considerations | N38: - | O38: - | P38: - | Q38: - | R38: yes | S38: - | T38: - | U38: M
A39: fdeath | B39: PhBlueGreens_fdeath | C39: parameter_input.dat | D39: - | E39: Multiplicative factor regarding mortality | F39: lognormal | G39: 0.5 | H39: 0.25 | I39: - | J39: - | K39: =VLOOKUP(B39,Tabelle1!$A$1:$C$351,2,FALSE) -> 0.52270802 | L39: =VLOOKUP(B39,Tabelle1!$A$1:$C$351,3,FALSE) -> 0.28827505 | M39: starting value for prior based on mechanistic considerations | N39: - | O39: - | P39: - | Q39: - | R39: yes | S39: - | T39: - | U39: M
A40: fdeath | B40: PhCryptophytes_fdeath | C40: parameter_input.dat | D40: - | E40: Multiplicative factor regarding mortality | F40: lognormal | G40: 0.5 | H40: 0.25 | I40: - | J40: - | K40: =VLOOKUP(B40,Tabelle1!$A$1:$C$351,2,FALSE) -> 0.4762042 | L40: =VLOOKUP(B40,Tabelle1!$A$1:$C$351,3,FALSE) -> 0.21355864 | M40: starting value for prior based on mechanistic considerations | N40: - | O40: - | P40: - | Q40: - | R40: yes | S40: - | T40: - | U40: M
A41: fdeath | B41: PhDiatoms_fdeath | C41: parameter_input.dat | D41: - | E41: Multiplicative factor regarding mortality | F41: lognormal | G41: 0.5 | H41: 0.25 | I41: - | J41: - | K41: =VLOOKUP(B41,Tabelle1!$A$1:$C$351,2,FALSE) -> 0.49529669 | L41: =VLOOKUP(B41,Tabelle1!$A$1:$C$351,3,FALSE) -> 0.24323244 | M41: starting value for prior based on mechanistic considerations | N41: - | O41: - | P41: - | Q41: - | R41: yes | S41: - | T41: - | U41: M
A42: fdeath | B42: PhGreens_fdeath | C42: parameter_input.dat | D42: - | E42: Multiplicative factor regarding mortality | F42: lognormal | G42: 0.5 | H42: 0.25 | I42: - | J42: - | K42: =VLOOKUP(B42,Tabelle1!$A$1:$C$351,2,FALSE) -> 0.50090409 | L42: =VLOOKUP(B42,Tabelle1!$A$1:$C$351,3,FALSE) -> 0.2524499 | M42: starting value for prior based on mechanistic considerations | N42: - | O42: - | P42: - | Q42: - | R42: yes | S42: - | T42: - | U42: M
A43: fgrotax | B43: PhBlueGreens_fgrotax | C43: parameter_input.dat | D43: - | E43: Taxon-specific modification factor of the growth rate | F43: Normal truncated | G43: 1 | H43: 0.25 | I43: 0.01 | J43: 1.99 | K43: =VLOOKUP(B43,Tabelle1!$A$1:$C$351,2,FALSE) -> 0.96888497 | L43: =VLOOKUP(B43,Tabelle1!$A$1:$C$351,3,FALSE) -> 0.25057761 | M43: starting value for prior based on mechanistic considerations | N43: - | O43: - | P43: - | Q43: - | R43: yes | S43: - | T43: - | U43: M
...

Sheet Input files
A1: Type of data in input file (e.g., daily temperature) | B1: File name in which data is contained | C1: Unit(s) of data | D1: Format of data (e.g., number of data points included) | E1: Name/meaning in real system | F1: Description of uncertainty of data in the input file | G1: References (including page #, table #, etc.) | H1: Description of system from which data originates | I1: Justification of relevance | J1: Estimation method (direct use of data, derived from original source, etc.) | K1: Description of methods and intermediary parameters used for compilation of input data (or reference to separate document) | L1: External files used for data estimation/ compilation (e.g., scripts, tables, etc.) or description of methodology
A2: nitrogen concentration | B2: environmental_conditions_variable | C2: mgN/L | D2: 4 timepoints | F2: no uncertainty addressed | G2: Provided by mesocosm GmbH | H2: Mesocosm studies | I2: Measured in the study | J2: Measured values for ammonia and ni | K2: Values from nitrate and ammonium were taken, N-content calculated, added and averaged across enclosures. | L2: R-file Prepare_exp_data.R
A3: phosphor concentration | B3: environmental_conditions_variable | C3: mgP/L | D3: 4 timepoints | F3: no uncertainty addressed | G3: Provided by mesocosm GmbH | H3: Mesocosm studies | I3: Measured in the study | J3: derived from original source | K3: Values from phosphate were taken, P-content calculated averaged across enclosures. | L3: R-file Prepare_exp_data.R
A4: temperature | B4: environmental_conditions_variable | C4: °C | D4: ca. 14 timepoints | F4: no uncertainty addressed | G4: Mesocosm GmbH | H4: Mesocosm studies | I4: intended for this project | J4: derived from original source | K4: Values were taken, mean across enclosures calculated | L4: R-file Prepare_exp_data.R
A5: shade | B5: environmental_conditions_variable | C5: % | D5: 5 timepoints | F5: no uncertainty addressed | G5: Mesocosm GmbH | H5: Mesocosm studies: measured coverage by macrophytes | I5: Proxy to cover shading effects caused by macrophytes. | J5: direct use of data | K5: - | L5: R-file Prepare_exp_data.R
A6: ionziation | B6: environmental_conditions_variable | C6: W/m2 | D6: daily mean | F6: no uncertainty addressed | G6: Mesocosm GmbH | H6: Station 35 km from FNU, rural | I6: intended for this project | J6: derived from original source | K6: daily mean calculated | L6: R-file Prepare_exp_data.R
A7: River width | B7: environmental_conditions_fix.txt | C7: m | D7: 4 values (1 value per Reach) | F7: no uncertainty addressed | G7: Mesocosm GmbH | H7: Mesocosm studies | I7: intended for this project | J7: direct use of data | K7: - | L7: -
A8: River reach length | B8: environmental_conditions_fix.txt | C8: m | D8: 4 values (1 value per Reach) | F8: no uncertainty addressed | G8: Mesocosm GmbH | H8: Mesocosm studies | I8: intended for this project | J8: direct use of data | K8: - | L8: -

Sheet Intermediary parameters
A1: Name of intermediary parameter | B1: Used in the calculation/ estimation of model parameter(s) | C1: Unit | D1: Biological name/meaning | E1: Estimated value | F1: Uncertainty (min, max of 95% interval or range of reported values) | G1: References (including page #, table #, etc.) | H1: Species used in measurement | I1: Experimental setting of measurement | J1: Justification of relevance | K1: Estimation method (direct use of data, derived from literature source, calibration) | L1: Description of methods used for parameter estimation (or reference to separate document) | M1: External files used for parameter estimation (e.g., scripts, tables, etc.) or description of methodology
A3: Conversion factors to extrapolate number of invertebrates in sample to abundance in mesocosm
A4: f.asellus | B4: abundance in mesocosm | C4: 1/m2 | D4: Conversion factors to extrapolate number of asellus, gammarus in sample to abundance in mesocosm | E4: 0.5 | F4: 0.1 - 1.3 | G4: Schmolke A. et al. (2021). Ecosystem modeling of mesocosm studies. Macroinvertebrates: estimating abundance per area from individuals per sample. Version of 4.March 2021 | H4: asellus aquaticus | I4: - | J4: developed by the consortium for this study | K4: direct use of data | L4: - | M4: -
A5: f.chiro | B5: abundance in mesocosm | C5: 1/m2 | D5: Conversion factors to extrapolate chironomidae, tanypodinae in sample to abundance in mesocosm | E5: 14.1 | F5: 12.2-16.1 | G5: Schmolke A. et al. (2021). Ecosystem modeling of mesocosm studies. Macroinvertebrates: estimating abundance per area from individuals per sample. Version of 4.March 2021 | H5: chironomidae | I5: - | J5: developed by the consortium for this study | K5: direct use of data | L5: - | M5: -
A6: f.snails | B6: abundance in mesocosm | C6: 1/m2 | D6: Conversion factors to extrapolate gastropoda in sample to abundance in mesocosm | E6: 1.3 | F6: 0.2-2.3 | G6: Schmolke A. et al. (2021). Ecosystem modeling of mesocosm studies. Macroinvertebrates: estimating abundance per area from individuals per sample. Version of 4.March 2021 | H6: snails | I6: - | J6: developed by the consortium for this study | K6: direct use of data | L6: - | M6: -
A7: f.oligo | B7: abundance in mesocosm | C7: 1/m2 | D7: Conversion factors to extrapolate hirudinea, oligochaeta in sample to abundance in mesocosm | E7: 11 | G7: Schmolke A. et al. (2021). Ecosystem modeling of mesocosm studies. Macroinvertebrates: estimating abundance per area from individuals per sample. Version of 4.March 2021 | H7: oligochaeta | I7: - | J7: developed by the consortium for this study | K7: direct use of data | L7: - | M7: -
A8: f.chaoborus | B8: abundance in mesocosm | C8: 1L | D8: Conversion factors to extrapolate chaoborus, cloeon, nepomorpha, odonata in sample to abundance in mesocosm | E8: 0.006 | G8: Schmolke A. et al. (2021). Ecosystem modeling of mesocosm studies. Macroinvertebrates: estimating abundance per area from individuals per sample. Version of 4.March 2021 | H8: chaoborus | I8: - | J8: developed by the consortium for this study | K8: direct use of data | L8: - | M8: -
A10: Other extrapolation factors
A11: no name (is calculated) | B11: Conversion to extrapolate from periphyton density on slide to density in mesocosm | C11: extrapolations assumes algae grows on ground and walls of the mesocosm. We ignore periphyton growing on macrophytes
A12: f.chla | B12: periphyton and phytoplankton biomass density | C12: ug Chl a / mg DW | D12: chlorophyll a content per mg of dry weight | E12: 6 | G12: see references belows
E13: 12 | G13: Runck 2007, Fig. 4 | H13: periphyton | I13: in streams, periphyton contained 1.0 - 1.45% Chlorophylla (AFDM) | J13: we model periphyton, values agree well with other
E14: 6 | G14: Strauss 2021: Compilation of correlations of chlorophyll a data and phytoplankton biomasses | H14: Chlorophyceae, Cyanobacteria, Diatoms and chrysophyceae, Cryptophyceae, Doinophyceae,
E15: 2.3 | G15: REYNOLDS, Colin S. The ecology of freshwater phytoplankton. Cambridge university press, 1984.
A17: Factors used to convert environmental conditions
A18: °C -> K
A19: Ammonium -> N
A20: Nitrate -> N
A21: Phosphate -> P

Sheet Unused references
A1: Name of input or intermediary parameter or input data | B1: Reference to source presenting relevant measurements | C1: Data presented in the source: species, experimental setting and design | D1: Reason the source was not used for parameter or input estimation

Sheet Tabelle1
B1: mean | C1: sd
A2: Algae_b | B2: 0.93918975 | C2: 0.03407624
A3: Algae_i0 | B3: 3.7549316e+09 | C3: 1.41494e+09
A4: Invertebrates_Ea | B4: 0.70672225 | C4: 0.010139978
A5: Invertebrates_b | B5: 0.69712103 | C5: 0.0071303223
A6: Invertebrates_i0 | B6: 5.2477295e+15 | C6: 1.7046488e+15
A7: FPOM_kminer | B7: 2.0845525 | C7: 2.0346036
A8: PhBlueGreens_KI | B8: 188.67426 | C8: 206.2315
A9: PhGreens_KI | B9: 165.1534 | C9: 160.98024
A10: PhDiatoms_KI | B10: 170.20159 | C10: 170.64492
A11: PhCryptophytes_KI | B11: 177.59851 | C11: 217.74482
A12: PeBlueGreens_KI | B12: 281.1575 | C12: 290.48006
A13: PeGreens_KI | B13: 260.52282 | C13: 245.71758
... A98: Chironomidae_Co19b_hab1_Dini | B98: 0.082869113 | C98: 0.0084577004
A99: CladoceraPhytophilous_Co14a_hab1_Dini | B99: NA | C99: NA
A100: CladoceraPhytophilous_Co16a_hab1_Dini | B100: 0.030885383 | C100: 0.0032301347
A101: CladoceraPhytophilous_Co18c_hab1_Dini | B101: 0.0012449083 | C101: 0.00012469284
A102: CladoceraPhytophilous_Co19b_hab1_Dini | B102: 0.0015765004 | C102: 0.00016494329
A103: CladoceraSmall_Co14a_hab1_Dini | B103: 0.0043083992 | C103: 0.00043329047
A104: CladoceraSmall_Co16a_hab1_Dini | B104: 0.13097066 | C104: 0.013772589
A105: CladoceraSmall_Co18c_hab1_Dini | B105: 0.069584341 | C105: 0.0072285385
A106: CladoceraSmall_Co19b_hab1_Dini | B106: 0.0097560945 | C106: 0.001062545
A107: Cloeon_Co14a_hab1_Dini | B107: 0.031856904 | C107: 0.0031216776
A108: Cloeon_Co16a_hab1_Dini | B108: 0.072323775 | C108: 0.0071104386
A109: Cloeon_Co18c_hab1_Dini | B109: 0.092307643 | C109: 0.0090245166
A110: Cloeon_Co19b_hab1_Dini | B110: 0.009449964 | C110: 0.00089272398
A111: CopepodaHerbivorous_Co14a_hab1_Dini | B111: NA | C111: NA
A112: CopepodaHerbivorous_Co16a_hab1_Dini | B112: NA | C112: NA
A113: CopepodaHerbivorous_Co18c_hab1_Dini | B113: 0.012137761 | C113: 0.0012252439
A114: CopepodaHerbivorous_Co19b_hab1_Dini | B114: NA | C114: NA
A115: CopepodaPredatory_Co14a_hab1_Dini | B115: 0.12285299 | C115: 0.012614163
A116: CopepodaPredatory_Co16a_hab1_Dini | B116: 0.08278419 | C116: 0.008028291
A117: CopepodaPredatory_Co18c_hab1_Dini | B117: 0.43090424 | C117: 0.042244766
A118: CopepodaPredatory_Co19b_hab1_Dini | B118: 0.05757026 | C118: 0.0057763894
A119: Daphnidae_Co14a_hab1_Dini | B119: NA | C119: NA
A120: Daphnidae_Co16a_hab1_Dini | B120: 1.0229039 | C120: 0.095848895
A121: Daphnidae_Co18c_hab1_Dini | B121: 0.28693456 | C121: 0.027456955
A122: Daphnidae_Co19b_hab1_Dini | B122: 0.28826116 | C122: 0.025851907
A123: Gammarus_Co14a_hab1_Dini | B123: NA | C123: NA
A124: Gammarus_Co16a_hab1_Dini | B124: 0.020324365 | C124: 0.0020858039
...
