Workbook

Sheet Info
A1: CRITERIA TO ANALYZE MODEL OUTPUTS WHEN SIMULATING EFFECTS
A3: Ecosystem modeling of mesocosm studies: Azoxystrobin effect calibration criteria
A4: Date: May 3 2022
A5: Prepared by: Chiara Accolla, Farah Abi-Akar, Amelie Schmolke
B6: The following sheets in this file provide the numerical effect criteria for relevant,treatment-related effects and templates for the reporting of the effect calibration outcomes. The following points summarize the steps for presentation of the simulated effects. Relevant, treatment-related effects that apply to consensus species groups were only observed in the highest treatment level (33 µg ai/L) applied in the 2019 AZT mesocsom study and thus, all criteria listed apply to this treatment level only. Please refer to the accompanying document "AZT_effect_criteria_June2022.docx" for details. Reporting on simulated effects in species groups without observed, treatment-related effects in the mesocosm study is not included in this template (see Section II. in the accompanying document).
B7: Instructions: In each tab, fill in the effect size percentage and ME in the rows under "Model Output" (e.g., in sheet "Phytoplankton", cells B12:O12 and B13:O13)
A9: **** | B9: 1) The effect direction needs to be captured (increase or decrease of chlorophyll-a/abundance)
A10: **** | B10: 2) The effect size, i.e., the relative difference between simulated treatment (%) and simulated control (%) (absolute value), must be at least as large as the day-specific %MDD when effects have been observed (table cells with yellow shading).
A11: **** | B11: 3) The effect size, i.e., the relative difference between simulated treatment (%) and simulated control (%) (absolute value), must be smaller than the day-specific %MDD when there are no observed effects.
A12: **** | B12: 4) If a clear recovery was identified, model should capture it (table cells with blue shading). Recovery is defined by a 20% threshold: effect size must be less than 20% in absolute value.
A13: **** | B13: 5) The Mean Error (ME), i.e., difference (absolute value) between simulated and observed % effect size is calculated for each sampling day (after first application) as indicated in the tables.
A15: **** | B15: Model results need to be discussed whenever they fail to meet the criteria.
A16: **** | B16: For the species groups with relevant, treatment-related effects, the number of false negatives (abs(%effectsim) < %MDD in yellow cells) and false positives (abs(%effectsim) ≥ %MDD in white cells) should be reported in the sheet "Final"
A18: **** | B18: Yellow cases show when relevant treatment-related effects were found in the mesocosm experiment. -> simulated effect-size >= MDD
A19: **** | B19: Blue cases show when recovery must happen in the simulation. -> simulated effect-size < 20 %
A20: **** | B20: Values in gray cells do not need to be compared to the corresponding MDD value, but effect-size values are required for the ME calculation
A21: **** | B21: White cases show when NO relevant treatment-related effects were found -> simulated effect-size < MDD
A22: **** | B22: ME: Mean Error, calculated as the absolute value of the difference between % simulated effect size and % observed effect size for each observation date.

Sheet Phytoplankton
A2: Species group
A3: Diatoms (3A) | B3: Mesocosm effect study
A4: Date | B4: 43630 | C4: 43634 | D4: 43638 | E4: 43643 | F4: 43650 | G4: 43656 | H4: 43664 | I4: 43671 | J4: 43678 | K4: 43684 | L4: 43692 | M4: 43698 | N4: 43705 | O4: 43712
A5: Day after first application | B5: day 1 | C5: day 5 | D5: day 9 | E5: day 14 | F5: day 21 | G5: day 27 | H5: day 35 | I5: day 42 | J5: day 49 | K5: day 55 | L5: day 63 | M5: day 69 | N5: day 76 | O5: day 83 | Q5: Effect: DECREASE in chlorophyll-a
A6: MDD [%] | B6: 48 | C6: 37 | D6: 32 | E6: 29 | F6: 44 | G6: 45 | H6: 47 | I6: 47 | J6: 49 | K6: 50 | L6: 57 | M6: 55 | N6: 53 | O6: 56
A7: Observed effect size [%] | B7: 91 | C7: -3 | D7: 31 | E7: 7 | F7: 99 | G7: 94 | H7: -4 | I7: -38 | J7: -32 | K7: -39 | L7: -60 | M7: -2 | N7: -45 | O7: -24
B9: Model output
A10: Date | B10: 43630 | C10: 43634 | D10: 43638 | E10: 43643 | F10: 43650 | G10: 43656 | H10: 43664 | I10: 43671 | J10: 43678 | K10: 43684 | L10: 43692 | M10: 43698 | N10: 43705 | O10: 43712
A11: Day after first application | B11: day 1 | C11: day 5 | D11: day 9 | E11: day 14 | F11: day 21 | G11: day 27 | H11: day 35 | I11: day 42 | J11: day 49 | K11: day 55 | L11: day 63 | M11: day 69 | N11: day 76 | O11: day 83 | R11: Y
A12: Simulated effect size [%] | B12: -0.3786822 | C12: 0.23455353 | D12: 0.81173926 | E12: 8.2519025 | F12: 48.23839 | G12: 2.5781714 | H12: -1.7637663 | I12: 4.6033509 | J12: 10.353764 | K12: -6.2563461 | L12: 2.7876796 | M12: -0.38508309 | N12: -0.017543078 | O12: 0.2236029 | R12: N
A13: ME | B13: =ABS(B12-B7) -> 91.378682 | C13: =ABS(C12-C7) -> 3.2345535 | D13: =ABS(D12-D7) -> 30.188261 | E13: =ABS(E12-E7) -> 1.2519025 | F13: =ABS(F12-F7) -> 50.76161 | G13: =ABS(G12-G7) -> 91.421829 | H13: =ABS(H12-H7) -> 2.2362337 | I13: =ABS(I12-I7) -> 42.603351 | ... O13: =ABS(O12-O7) -> 24.223603
A15: Abs Sim - MDD | B15: =ABS(B12)-B6 -> -47.621318 | C15: =ABS(C12)-C6 -> -36.765446 | D15: =ABS(D12)-D6 -> -31.188261 | E15: =ABS(E12)-E6 -> -20.748098 | F15: =ABS(F12)-F6 -> 4.2383902 | G15: =ABS(G12)-G6 -> -42.421829 | H15: =ABS(H12)-H6 -> -45.236234 | I15: =ABS(I12)-I6 -> -42.396649 | ... O15: =ABS(O12)-O6 -> -55.776397
A16: Abs Mess - MDD | B16: =ABS(B7)-B6 -> 43 | C16: =ABS(C7)-C6 -> -34 | D16: =ABS(D7)-D6 -> -1 | E16: =ABS(E7)-E6 -> -22 | F16: =ABS(F7)-F6 -> 55 | G16: =ABS(G7)-G6 -> 49 | H16: =ABS(H7)-H6 -> -43 | I16: =ABS(I7)-I6 -> -9 | ... O16: =ABS(O7)-O6 -> -32
F17: f pos | L17: f neg | N17: f neg
A20: Cryptophytes (3A) | B20: Mesocosm effect study
A21: Date | B21: 43630 | C21: 43634 | D21: 43638 | E21: 43643 | F21: 43650 | G21: 43656 | H21: 43664 | I21: 43671 | J21: 43678 | K21: 43684 | L21: 43692 | M21: 43698 | N21: 43705 | O21: 43712
A22: Day after first application | B22: day 1 | C22: day 5 | D22: day 9 | E22: day 14 | F22: day 21 | G22: day 27 | H22: day 35 | I22: day 42 | J22: day 49 | K22: day 55 | L22: day 63 | M22: day 69 | N22: day 76 | O22: day 83 | Q22: Effect: DECREASE in chlorophyll-a
A23: MDD [%] | B23: 48 | C23: 41 | D23: 48 | E23: 71 | F23: 92 | G23: 66 | H23: 73 | I23: 47 | J23: 85 | K23: 44 | L23: 85 | M23: 81 | N23: 86 | O23: 44
A24: Observed effect size [%] | B24: 126 | C24: -26 | D24: -17 | E24: -74 | F24: 2 | G24: 31 | H24: 66 | I24: -80 | J24: -69 | K24: -62 | L24: -71 | M24: -36 | N24: -74 | O24: -36
B26: Model output
A27: Date | B27: 43630 | C27: 43634 | D27: 43638 | E27: 43643 | F27: 43650 | G27: 43656 | H27: 43664 | I27: 43671 | J27: 43678 | K27: 43684 | L27: 43692 | M27: 43698 | N27: 43705 | O27: 43712
A28: Day after first application | B28: day 1 | C28: day 5 | D28: day 9 | E28: day 14 | F28: day 21 | G28: day 27 | H28: day 35 | I28: day 42 | J28: day 49 | K28: day 55 | L28: day 63 | M28: day 69 | N28: day 76 | O28: day 83
A29: Simulated effect size [%] | B29: -5.9904179 | C29: -5.7194068 | D29: -1.1179746 | E29: 14.375187 | F29: 10.698925 | G29: 12.769497 | H29: 3.4425021 | I29: 1.8248628 | J29: 7.1428571 | K29: 2.9935412 | L29: 3.3910068 | M29: -4.7383604 | N29: 0.77974776 | O29: 0.35708332
A30: ME | B30: =ABS(B29-B24) -> 131.99042 | C30: =ABS(C29-C24) -> 20.280593 | D30: =ABS(D29-D24) -> 15.882025 | E30: =ABS(E29-E24) -> 88.375187 | F30: =ABS(F29-F24) -> 8.6989252 | G30: =ABS(G29-G24) -> 18.230503 | H30: =ABS(H29-H24) -> 62.557498 | I30: =ABS(I29-I24) -> 81.824863 | ... O30: =ABS(O29-O24) -> 36.357083
A32: Abs Sim - MDD | B32: =ABS(B29)-B23 -> -42.009582 | C32: =ABS(C29)-C23 -> -35.280593 | D32: =ABS(D29)-D23 -> -46.882025 | E32: =ABS(E29)-E23 -> -56.624813 | F32: =ABS(F29)-F23 -> -81.301075 | G32: =ABS(G29)-G23 -> -53.230503 | H32: =ABS(H29)-H23 -> -69.557498 | I32: =ABS(I29)-I23 -> -45.175137 | ... O32: =ABS(O29)-O23 -> -43.642917
A33: Abs Mess - MDD | B33: =ABS(B24)-B23 -> 78 | C33: =ABS(C24)-C23 -> -15 | D33: =ABS(D24)-D23 -> -31 | E33: =ABS(E24)-E23 -> 3 | F33: =ABS(F24)-F23 -> -90 | G33: =ABS(G24)-G23 -> -35 | H33: =ABS(H24)-H23 -> -7 | I33: =ABS(I24)-I23 -> 33 | ... O33: =ABS(O24)-O23 -> -8
E34: f neg | I34: f neg | K34: f neg
A37: New from gaiac
A38: Green algae | B38: Mesocosm effect study
A39: Date | B39: 43630 | C39: 43634 | D39: 43638 | E39: 43643 | F39: 43650 | G39: 43656 | H39: 43664 | I39: 43671 | J39: 43678 | K39: 43684 | L39: 43692 | M39: 43698 | N39: 43705 | O39: 43712 | Q39: Effect: INCREASE in chlorophyll-a
A40: Day after first application | B40: day 1 | C40: day 5 | D40: day 9 | E40: day 14 | F40: day 21 | G40: day 27 | H40: day 35 | I40: day 42 | J40: day 49 | K40: day 55 | L40: day 63 | M40: day 69 | N40: day 76 | O40: day 83
A41: MDD [%] | B41: 73 | C41: 35 | D41: 56 | E41: 50 | F41: 64 | G41: 80 | H41: 92 | I41: 90 | J41: 104 | K41: 111 | L41: 102 | M41: 109 | N41: 132 | O41: 135
A42: Observed effect size [%] | B42: -6.2049062 | C42: 106.98925 | D42: 283.37292 | E42: 153.70205 | F42: 665.61922 | G42: 532.35294 | H42: -55.308092 | I42: 27.12916 | J42: 131.99153 | K42: -26.649077 | L42: -78.307146 | M42: 35.9375 | N42: 626.06061 | O42: 275.22124
B44: Model output
A45: Date | B45: 43630 | C45: 43634 | D45: 43638 | E45: 43643 | F45: 43650 | G45: 43656 | H45: 43664 | I45: 43671 | J45: 43678 | K45: 43684 | L45: 43692 | M45: 43698 | N45: 43705 | O45: 43712
A46: Day after first application | B46: day 1 | C46: day 5 | D46: day 9 | E46: day 14 | F46: day 21 | G46: day 27 | H46: day 35 | I46: day 42 | J46: day 49 | K46: day 55 | L46: day 63 | M46: day 69 | N46: day 76 | O46: day 83 | R46: Y
A47: Simulated effect size [%] | B47: 8.3521792 | C47: 8.8536138 | D47: 15.776506 | E47: 53.077452 | F47: 56.088176 | G47: 268.51964 | H47: 168.66698 | I47: 115.05433 | J47: 326.93752 | K47: -8.1807957 | L47: -2.4593372 | M47: -0.48284733 | N47: -1.9826964 | O47: -1.4412527 | R47: N
A48: ME | B48: =ABS(B47-B42) -> 14.557085 | C48: =ABS(C47-C42) -> 98.135634 | D48: =ABS(D47-D42) -> 267.59642 | E48: =ABS(E47-E42) -> 100.6246 | F48: =ABS(F47-F42) -> 609.53105 | G48: =ABS(G47-G42) -> 263.8333 | H48: =ABS(H47-H42) -> 223.97507 | I48: =ABS(I47-I42) -> 87.925172 | ... O48: =ABS(O47-O42) -> 276.66249
A50: Abs Sim - MDD | B50: =ABS(B47)-B41 -> -64.647821 | C50: =ABS(C47)-C41 -> -26.146386 | D50: =ABS(D47)-D41 -> -40.223494 | E50: =ABS(E47)-E41 -> 3.0774524 | F50: =ABS(F47)-F41 -> -7.9118237 | G50: =ABS(G47)-G41 -> 188.51964 | H50: =ABS(H47)-H41 -> 76.666979 | I50: =ABS(I47)-I41 -> 25.054332 | ... O50: =ABS(O47)-O41 -> -133.55875
A51: Abs Mess - MDD | B51: =ABS(B42)-B41 -> -66.795094 | C51: =ABS(C42)-C41 -> 71.989247 | D51: =ABS(D42)-D41 -> 227.37292 | E51: =ABS(E42)-E41 -> 103.70205 | F51: =ABS(F42)-F41 -> 601.61922 | G51: =ABS(G42)-G41 -> 452.35294 | H51: =ABS(H42)-H41 -> -36.691908 | I51: =ABS(I42)-I41 -> -62.87084 | ... O51: =ABS(O42)-O41 -> 140.22124
...

Sheet Copepoda predatory
A1: **** NOTE | B1: You have to fill this table (and the table in the next sheet) only if you explicitly represented Nauplii
A2: Used by gaiac
A4: Species group
A5: Copepodit + adults (5B) | B5: Mesocosm effect study
A6: Date | B6: 43630 | C6: 43636 | D6: 43638 | E6: 43644 | F6: 43651 | G6: 43658 | H6: 43665 | I6: 43672 | J6: 43679 | K6: 43686 | L6: 43693 | M6: 43700 | N6: 43706 | O6: 43714
A7: Day after first application | B7: day 1 | C7: day 7 | D7: day 9 | E7: day 15 | F7: day 22 | G7: day 29 | H7: day 36 | I7: day 43 | J7: day 50 | K7: day 57 | L7: day 64 | M7: day 71 | N7: day 77 | O7: day 85 | Q7: Effect: DECREASE in abundance
A8: MDD [%] | B8: 51 | C8: 40 | D8: 51 | E8: 60 | F8: 46 | G8: 38 | H8: 53 | I8: 53 | J8: 51 | K8: 47 | L8: 34 | M8: 56 | N8: 45 | O8: 59
A9: Observed effect size [%] | B9: 38 | C9: -64 | D9: -86 | E9: -97 | F9: -66 | G9: -63 | H9: -80 | I9: -81 | J9: -80 | K9: -73 | L9: -72 | M9: 4 | N9: -36 | O9: 2
B11: Model output | R11: Y
A12: Date | B12: 43630 | C12: 43636 | D12: 43638 | E12: 43644 | F12: 43651 | G12: 43658 | H12: 43665 | I12: 43672 | J12: 43679 | K12: 43686 | L12: 43693 | M12: 43700 | N12: 43706 | O12: 43714 | R12: N
A13: Day after first application | B13: day 1 | C13: day 7 | D13: day 9 | E13: day 15 | F13: day 22 | G13: day 29 | H13: day 36 | I13: day 43 | J13: day 50 | K13: day 57 | L13: day 64 | M13: day 71 | N13: day 77 | O13: day 85
A14: Simulated effect size [%] | B14: -2.0326435 | C14: -81.893163 | D14: -90.288281 | E14: -95.309292 | F14: -96.385781 | G14: -96.454406 | H14: -96.288098 | I14: -96.113464 | J14: -94.982079 | K14: -94.468085 | L14: -93.432836 | M14: -92.352941 | N14: -94.705882 | O14: -86
A15: ME | B15: =ABS(B14-B9) -> 40.032644 | C15: =ABS(C14-C9) -> 17.893163 | D15: =ABS(D14-D9) -> 4.2882814 | E15: =ABS(E14-E9) -> 1.6907085 | F15: =ABS(F14-F9) -> 30.385781 | G15: =ABS(G14-G9) -> 33.454406 | H15: =ABS(H14-H9) -> 16.288098 | I15: =ABS(I14-I9) -> 15.113464 | ... O15: =ABS(O14-O9) -> 88
A17: Abs Sim - MDD | B17: =ABS(B14)-B8 -> -48.967356 | C17: =ABS(C14)-C8 -> 41.893163 | D17: =ABS(D14)-D8 -> 39.288281 | E17: =ABS(E14)-E8 -> 35.309292 | F17: =ABS(F14)-F8 -> 50.385781 | G17: =ABS(G14)-G8 -> 58.454406 | H17: =ABS(H14)-H8 -> 43.288098 | I17: =ABS(I14)-I8 -> 43.113464 | ... O17: =ABS(O14)-O8 -> 27
A18: Abs Mess - MDD | B18: =ABS(B9)-B8 -> -13 | C18: =ABS(C9)-C8 -> 24 | D18: =ABS(D9)-D8 -> 35 | E18: =ABS(E9)-E8 -> 37 | F18: =ABS(F9)-F8 -> 20 | G18: =ABS(G9)-G8 -> 25 | H18: =ABS(H9)-H8 -> 27 | I18: =ABS(I9)-I8 -> 28 | ... O18: =ABS(O9)-O8 -> -57
M19: f pos | N19: f pos | O19: f pos
Q21: =AVERAGE(B15:O15) -> 32.863455

Sheet Nauplia
A1: **** NOTE | B1: You have to fill this table (and the table in the previous sheet) only if you explicitly represented Nauplii
A3: Species group
A4: Nauplii (5B) | B4: Mesocosm effect study
A5: Date | B5: 43630 | C5: 43636 | D5: 43638 | E5: 43644 | F5: 43651 | G5: 43658 | H5: 43665 | I5: 43672 | J5: 43679 | K5: 43686 | L5: 43693 | M5: 43700 | N5: 43706 | O5: 43714
A6: Day after first application | B6: day 1 | C6: day 7 | D6: day 9 | E6: day 15 | F6: day 22 | G6: day 29 | H6: day 36 | I6: day 43 | J6: day 50 | K6: day 57 | L6: day 64 | M6: day 71 | N6: day 77 | O6: day 85 | Q6: Effect: DECREASE in abundance
A7: MDD [%] | B7: 47 | C7: 29 | D7: 54 | E7: 66 | F7: 67 | G7: 51 | H7: 53 | I7: 43 | J7: 55 | K7: 60 | L7: 57 | M7: 56 | N7: 65 | O7: 71
A8: Observed effect size [%] | B8: -31 | C8: -97 | D8: -100 | E8: -100 | F8: -100 | G8: -99 | H8: -99 | I8: -93 | J8: -99 | K8: -99 | L8: -99 | M8: -86 | N8: -52 | O8: -97
B10: Model output
A11: Date | B11: 43630 | C11: 43636 | D11: 43638 | E11: 43644 | F11: 43651 | G11: 43658 | H11: 43665 | I11: 43672 | J11: 43679 | K11: 43686 | L11: 43693 | M11: 43700 | N11: 43706 | O11: 43714 | R11: Y
A12: Day after first application | B12: day 1 | C12: day 7 | D12: day 9 | E12: day 15 | F12: day 22 | G12: day 29 | H12: day 36 | I12: day 43 | J12: day 50 | K12: day 57 | L12: day 64 | M12: day 71 | N12: day 77 | O12: day 85 | R12: N
A13: Simulated effect size [%] | B13: -26.072296 | C13: -74.154361 | D13: -76.257271 | E13: -58.174077 | F13: -90.662665 | G13: -88.683857 | H13: -90.054164 | I13: -84.96112 | J13: -41.856148 | K13: -92.202462 | L13: -84.152047 | M13: -81.756757 | N13: -79.333333 | O13: -30
A14: ME | B14: =ABS(B13-B8) -> 4.927704 | C14: =ABS(C13-C8) -> 22.845639 | D14: =ABS(D13-D8) -> 23.742729 | E14: =ABS(E13-E8) -> 41.825923 | F14: =ABS(F13-F8) -> 9.3373355 | G14: =ABS(G13-G8) -> 10.316143 | H14: =ABS(H13-H8) -> 8.9458364 | I14: =ABS(I13-I8) -> 8.0388802 | ... O14: =ABS(O13-O8) -> 67
A16: Abs Sim - MDD | B16: =ABS(B13)-B7 -> -20.927704 | C16: =ABS(C13)-C7 -> 45.154361 | D16: =ABS(D13)-D7 -> 22.257271 | E16: =ABS(E13)-E7 -> -7.8259233 | F16: =ABS(F13)-F7 -> 23.662665 | G16: =ABS(G13)-G7 -> 37.683857 | H16: =ABS(H13)-H7 -> 37.054164 | I16: =ABS(I13)-I7 -> 41.96112 | ... O16: =ABS(O13)-O7 -> -41
A17: Abs Mess - MDD | B17: =ABS(B8)-B7 -> -16 | C17: =ABS(C8)-C7 -> 68 | D17: =ABS(D8)-D7 -> 46 | E17: =ABS(E8)-E7 -> 34 | F17: =ABS(F8)-F7 -> 33 | G17: =ABS(G8)-G7 -> 48 | H17: =ABS(H8)-H7 -> 46 | I17: =ABS(I8)-I7 -> 50 | ... O17: =ABS(O8)-O7 -> 26
E18: f neg | J18: f neg | O18: f neg

Sheet Rotifera herbivorous 2
A2: Species group
A3: Sum Rotatoria (5B+) | B3: Mesocosm effect study
A4: Date | B4: 43630 | C4: 43636 | D4: 43638 | E4: 43644 | F4: 43651 | G4: 43658 | H4: 43665 | I4: 43672 | J4: 43679 | K4: 43686 | L4: 43693 | M4: 43700 | N4: 43706 | O4: 43714
A5: Day after first application | B5: day 1 | C5: day 7 | D5: day 9 | E5: day 15 | F5: day 22 | G5: day 29 | H5: day 36 | I5: day 43 | J5: day 50 | K5: day 57 | L5: day 64 | M5: day 71 | N5: day 77 | O5: day 85 | Q5: Effect: INCREASE in abundance
A6: MDD [%] | B6: 71 | C6: 73 | D6: 75 | E6: 86 | F6: 57 | G6: 54 | H6: 56 | I6: 52 | J6: 64 | K6: 67 | L6: 69 | M6: 66 | N6: 71 | O6: 63
A7: Observed effect size [%] | B7: -32 | C7: 58 | D7: 56 | E7: 119 | F7: 156 | G7: 251 | H7: 249 | I7: 317 | J7: 584 | K7: 337 | L7: 159 | M7: 167 | N7: 446 | O7: 230
B9: Model output
A10: Date | B10: 43630 | C10: 43636 | D10: 43638 | E10: 43644 | F10: 43651 | G10: 43658 | H10: 43665 | I10: 43672 | J10: 43679 | K10: 43686 | L10: 43693 | M10: 43700 | N10: 43706 | O10: 43714
A11: Day after first application | B11: day 1 | C11: day 7 | D11: day 9 | E11: day 15 | F11: day 22 | G11: day 29 | H11: day 36 | I11: day 43 | J11: day 50 | K11: day 57 | L11: day 64 | M11: day 71 | N11: day 77 | O11: day 85 | R11: Y
A12: Simulated effect size [%] | B12: -1.191899 | C12: 1.7574314 | D12: 4.7654083 | E12: 41.617569 | F12: 128.4497 | G12: 398.22824 | H12: 824.6878 | I12: 1382.4517 | J12: 4702.4433 | K12: 5009.8165 | L12: 2364.9179 | M12: 1102.2669 | N12: 484.24828 | O12: 135.36904 | R12: N
A13: ME | B13: =ABS(B12-B7) -> 30.808101 | C13: =ABS(C12-C7) -> 56.242569 | D13: =ABS(D12-D7) -> 51.234592 | E13: =ABS(E12-E7) -> 77.382431 | F13: =ABS(F12-F7) -> 27.550297 | G13: =ABS(G12-G7) -> 147.22824 | H13: =ABS(H12-H7) -> 575.6878 | I13: =ABS(I12-I7) -> 1065.4517 | ... O13: =ABS(O12-O7) -> 94.630956
A15: Abs Sim - MDD | B15: =ABS(B12)-B6 -> -69.808101 | C15: =ABS(C12)-C6 -> -71.242569 | D15: =ABS(D12)-D6 -> -70.234592 | E15: =ABS(E12)-E6 -> -44.382431 | F15: =ABS(F12)-F6 -> 71.449703 | G15: =ABS(G12)-G6 -> 344.22824 | H15: =ABS(H12)-H6 -> 768.6878 | I15: =ABS(I12)-I6 -> 1330.4517 | ... O15: =ABS(O12)-O6 -> 72.369044
A16: Abs Mess - MDD | B16: =ABS(B7)-B6 -> -39 | C16: =ABS(C7)-C6 -> -15 | D16: =ABS(D7)-D6 -> -19 | E16: =ABS(E7)-E6 -> 33 | F16: =ABS(F7)-F6 -> 99 | G16: =ABS(G7)-G6 -> 197 | H16: =ABS(H7)-H6 -> 193 | I16: =ABS(I7)-I6 -> 265 | ... O16: =ABS(O7)-O6 -> 167
F17: ???

Sheet Daphnidae
A2: Species group
A3: Daphnia sp. (3A) | B3: Mesocosm effect study
A4: Date | B4: 43630 | C4: 43636 | D4: 43638 | E4: 43644 | F4: 43651 | G4: 43658 | H4: 43665 | I4: 43672 | J4: 43679 | K4: 43686 | L4: 43693 | M4: 43700 | N4: 43706 | O4: 43714
A5: Day after first application | B5: day 1 | C5: day 7 | D5: day 9 | E5: day 15 | F5: day 22 | G5: day 29 | H5: day 36 | I5: day 43 | J5: day 50 | K5: day 57 | L5: day 64 | M5: day 71 | N5: day 77 | O5: day 85 | Q5: Effect: DECREASE in abundance
A6: MDD [%] | B6: 56 | C6: 75 | D6: 56 | E6: 64 | F6: 90 | G6: 78 | H6: 79 | I6: 65 | J6: 64 | K6: 78 | L6: 64 | M6: 60 | N6: 72 | O6: 65
A7: Observed effect size [%] | B7: -77 | C7: -92 | D7: -95 | E7: -95 | F7: -91 | G7: -85 | H7: -84 | I7: -10 | J7: -35 | K7: -17 | L7: 25 | M7: -2 | N7: 99 | O7: -26
B9: Model output
A10: Date | B10: 43630 | C10: 43636 | D10: 43638 | E10: 43644 | F10: 43651 | G10: 43658 | H10: 43665 | I10: 43672 | J10: 43679 | K10: 43686 | L10: 43693 | M10: 43700 | N10: 43706 | O10: 43714
A11: Day after first application | B11: day 1 | C11: day 7 | D11: day 9 | E11: day 15 | F11: day 22 | G11: day 29 | H11: day 36 | I11: day 43 | J11: day 50 | K11: day 57 | L11: day 64 | M11: day 71 | N11: day 77 | O11: day 85 | R11: Y
A12: Simulated effect size [%] | B12: 0.78918294 | C12: -87.675459 | D12: -93.540294 | E12: -98.573396 | F12: -99.53638 | G12: -99.297022 | H12: -96.872572 | I12: -86.335691 | J12: -61.817471 | K12: 3.1173302 | L12: -2.1204543 | M12: -2.3605347 | N12: 3.9402546 | O12: -5.0090598 | R12: N
A13: ME | B13: =ABS(B12-B7) -> 77.789183 | C13: =ABS(C12-C7) -> 4.3245406 | D13: =ABS(D12-D7) -> 1.4597056 | E13: =ABS(E12-E7) -> 3.5733955 | F13: =ABS(F12-F7) -> 8.5363799 | G13: =ABS(G12-G7) -> 14.297022 | H13: =ABS(H12-H7) -> 12.872572 | I13: =ABS(I12-I7) -> 76.335691 | ... O13: =ABS(O12-O7) -> 20.99094
A15: Abs Sim - MDD | B15: =ABS(B12)-B6 -> -55.210817 | C15: =ABS(C12)-C6 -> 12.675459 | D15: =ABS(D12)-D6 -> 37.540294 | E15: =ABS(E12)-E6 -> 34.573396 | F15: =ABS(F12)-F6 -> 9.5363799 | G15: =ABS(G12)-G6 -> 21.297022 | H15: =ABS(H12)-H6 -> 17.872572 | I15: =ABS(I12)-I6 -> 21.335691 | ... O15: =ABS(O12)-O6 -> -59.99094
A16: Abs Mess - MDD | B16: =ABS(B7)-B6 -> 21 | C16: =ABS(C7)-C6 -> 17 | D16: =ABS(D7)-D6 -> 39 | E16: =ABS(E7)-E6 -> 31 | F16: =ABS(F7)-F6 -> 1 | G16: =ABS(G7)-G6 -> 7 | H16: =ABS(H7)-H6 -> 5 | I16: =ABS(I7)-I6 -> -55 | ... O16: =ABS(O7)-O6 -> -39
B17: f neg | F17: ??? | G17: ??? | H17: ??? | I17: f pos

Sheet Copepoda predatory - ALL
A1: Not Used by gaiac
A3: **** NOTE | B3: You have to fill this table only if you DID NOT explicitly represented Nauplii
A5: Species group
A6: Sum Copepoda (5B) | B6: Mesocosm effect study
A7: Date | B7: 43630 | C7: 43636 | D7: 43638 | E7: 43644 | F7: 43651 | G7: 43658 | H7: 43665 | I7: 43672 | J7: 43679 | K7: 43686 | L7: 43693 | M7: 43700 | N7: 43706 | O7: 43714
A8: Day after first application | B8: day 1 | C8: day 7 | D8: day 9 | E8: day 15 | F8: day 22 | G8: day 29 | H8: day 36 | I8: day 43 | J8: day 50 | K8: day 57 | L8: day 64 | M8: day 71 | N8: day 77 | O8: day 85 | Q8: Effect: DECREASE in abundance
A9: MDD [%] | B9: 45 | C9: 29 | D9: 44 | E9: 64 | F9: 46 | G9: 36 | H9: 43 | I9: 40 | J9: 41 | K9: 43 | L9: 49 | M9: 49 | N9: 58 | O9: 66
A10: Observed Effect size [%] | B10: -27 | C10: -96 | D10: -99 | E10: -100 | F10: -99 | G10: -98 | H10: -97 | I10: -91 | J10: -96 | K10: -96 | L10: -97 | M10: -78 | N10: -49 | O10: -91
B12: Model output
A13: Date | B13: 43630 | C13: 43636 | D13: 43638 | E13: 43644 | F13: 43651 | G13: 43658 | H13: 43665 | I13: 43672 | J13: 43679 | K13: 43686 | L13: 43693 | M13: 43700 | N13: 43706 | O13: 43714
A14: Day after first application | B14: day 1 | C14: day 7 | D14: day 9 | E14: day 15 | F14: day 22 | G14: day 29 | H14: day 36 | I14: day 43 | J14: day 50 | K14: day 57 | L14: day 64 | M14: day 71 | N14: day 77 | O14: day 85 | R14: Y
A15: Effect size [%] | R15: N
A16: ME | B16: =ABS(B15-B10) -> 27 | C16: =ABS(C15-C10) -> 96 | D16: =ABS(D15-D10) -> 99 | E16: =ABS(E15-E10) -> 100 | F16: =ABS(F15-F10) -> 99 | G16: =ABS(G15-G10) -> 98 | H16: =ABS(H15-H10) -> 97 | I16: =ABS(I15-I10) -> 91 | ... O16: =ABS(O15-O10) -> 91

Sheet Cladocera small
A1: Not Used by gaiac
A3: Species group
A4: Chydorus sphaericus (3A+) | B4: Mesocosm effect study
A5: Date | B5: 43630 | C5: 43636 | D5: 43638 | E5: 43644 | F5: 43651 | G5: 43658 | H5: 43665 | I5: 43672 | J5: 43679 | K5: 43686 | L5: 43693 | M5: 43700 | N5: 43706 | O5: 43714
A6: Day after first application | B6: day 1 | C6: day 7 | D6: day 9 | E6: day 15 | F6: day 22 | G6: day 29 | H6: day 36 | I6: day 43 | J6: day 50 | K6: day 57 | L6: day 64 | M6: day 71 | N6: day 77 | O6: day 85 | Q6: Effect: INCREASE in abundance
A7: MDD [%] | B7: 56 | C7: 60 | D7: 86 | E7: 75 | F7: 67 | G7: 66 | H7: 82 | I7: 67 | J7: 62 | K7: 76 | L7: 93 | M7: 83 | N7: 78 | O7: 80
A8: Observed effect size [%] | B8: 19 | C8: 262 | D8: 220 | E8: 63 | F8: 6 | G8: 112 | H8: 87 | I8: 14 | J8: 101 | K8: -98 | L8: -72 | M8: 17 | N8: 22 | O8: -66
B10: Model output
A11: Date | B11: 43630 | C11: 43636 | D11: 43638 | E11: 43644 | F11: 43651 | G11: 43658 | H11: 43665 | I11: 43672 | J11: 43679 | K11: 43686 | L11: 43693 | M11: 43700 | N11: 43706 | O11: 43714
A12: Day after first application | B12: day 1 | C12: day 7 | D12: day 9 | E12: day 15 | F12: day 22 | G12: day 29 | H12: day 36 | I12: day 43 | J12: day 50 | K12: day 57 | L12: day 64 | M12: day 71 | N12: day 77 | O12: day 85 | R12: Y
A13: Simulated effect size [%] | R13: N
A14: ME | B14: =ABS(B13-B8) -> 19 | C14: =ABS(C13-C8) -> 262 | D14: =ABS(D13-D8) -> 220 | E14: =ABS(E13-E8) -> 63 | F14: =ABS(F13-F8) -> 6 | G14: =ABS(G13-G8) -> 112 | H14: =ABS(H13-H8) -> 87 | I14: =ABS(I13-I8) -> 14 | ... O14: =ABS(O13-O8) -> 66

Sheet Final
A1: Summary of model performance relative to effect criteria
B2: False negatives | C2: False positives | D2: Avg. ME | F2: Definitions
A3: Diatoms | B3: 2 | C3: 1 | D3: =AVERAGE(Phytoplankton!B13:O13) -> 37.270178 | F3: False negatives: | G3: abs(%effectsim) < %MDD on sampling dates with treatment-related effects observed in the 2019 AZT mesocoms study (yellow cells)
A4: Cryptophytes | B4: 3 | C4: 0 | D4: =AVERAGE(Phytoplankton!B30:O30) -> 56.126135 | F4: False positives: | G4: abs(%effectsim) ≥ %MDD on sampling dates without treatment-related effects observed in the 2019 AZT mesocoms study (white cells)
A5: Green algae | B5: 3 | C5: 2 (1) | D5: =AVERAGE(Phytoplankton!B48:O48) -> 206.89761
A6: Total Chl.a | B6: 1 | C6: 2 | D6: =AVERAGE(Phytoplankton!B66:O66) -> 60.532273 | F6: Avg. ME: | G6: Average of ME values comparing observed and simulated % effect sizes calculated for each sampling date
A7: Sum Copepoda | B7: 0 | C7: 3 | D7: =AVERAGE('Copepoda predatory'!B15:O15) -> 32.863455
A8: Nauplii | B8: 3 | C8: 0 | D8: =AVERAGE(Nauplia!B14:O14) -> 21.953294
A9: Sum Rotatoria | B9: 0 | C9: 0 (1) | D9: =AVERAGE('Rotifera herbivorous 2'!B13:O13) -> 1006.9221
A10: Daphnia | B10: 1 | C10: 1 (3) | D10: =AVERAGE(Daphnidae!B13:O13) -> 27.832498
A12: In brackets:
A13: Days with mismatch of the MDD criterion, but still acceptable simulation.
